---
layout:     post
title:      异常
subtitle:   exception
date:       2019-10-27
author:     BY
header-img: img/post-bg-cook.jpg
catalog: true
tags:
    - java
---

### 异常

> 一种程序运行时机制

        应当清楚try中抛出的异常，catch参数类型需要和try中抛出的异常相匹配
        若不匹配，catch不会生效，仍由JVM自己处理try放置可能会抛出异常的代码
          
	 catch参数类型得匹配，catch可以有多个
         finally用来善后，不能有return
         throw抛出异常（创建一个异常对象）
         throw异常说明，表明一个方法可能会抛出哪些异常
	
**异常举例:**        

```java
public static int divide(int x,int y){
  if(y == 0){
    return -1;
  }
  return x/y;
}
//但是这样会产生返回值出现错误的情况，有可能除数是-1
//因此采用方法类Integer,返回值为null来表明这种情况
public static Integer divide(int x,int y){
  if(y == 0){
    return null;
  }
  retunr x / y;
}
```
        
> try中异常可能多种，可使用Exception这个异常类的父类来代替子类

**举例：**
```java
Scanner scanner = new Scanner(System.in);
        try {
            int age = scanner.nextInt();
        } catch (Exception e) {
	    //打印栈中追踪信息
            e.printStackTrace();
        } finally {
            scanner.close();
        }
```

> 如果代码中抛出异常后未立即处理的话，就会沿着调用栈向着调用者传递（向下传递）
    
        方法体 -> main函数 -> JVM

**举例：**
```java
try{
            fun3();
        }catch (ArrayIndexOutOfBoundsException e){
            e.printStackTrace();
        }
```
         
         finally执行是在方法return之前
         finally中不建议使用return返回一个值
         
**举例：**         
```java
try{
            int[] arr = {1,2,3,4};
            System.out.println("before");
            //System.out.println(arr[4]);
            System.out.println("after");
            return 10;
        }catch(ArrayIndexOutOfBoundsException e){
            e.printStackTrace();
        }finally {
            return 20;
        }
    }
```
         
> 捕获异常catch,抛出异常throw

          使用throws关键字来提示程序员一个方法可能会抛出哪些异常
	  throws在方法后面，异常声明，声明之后还是交由JVM处理
	  throw是程序员自己抛出的异常
	  不用再try,catch,更有利于自定制异常	  
          更有利于代码维护，也有利于编译器校验
	  
          
**例如：**
```java
//异常说明
public static int divide2(int x,int y) throws ArithmeticException {
        if (y == 0) {
	    //自己抛出异常
            throw new ArithmeticException("除数为0");
        }
        return x / y;
    }
```

> 异常分为受查异常和非受查异常
	
        派生于Error类或者RuntimeException类的称为受查异常，其他的为非受查异常
        若有受查异常（编译时异常），必须显式处理

> 自定制异常往往不是创建一个类，而是需要一个系列

```java
public static int fun5() /* 或者加入throw FileNotFoundException,之后由main方法处理*/{
        //尝试读一个文件
        File file = new File("d:/test.txt");
        Scanner scanner = null;
        try {
            scanner = new Scanner(file);
        } catch (FileNotFoundException e) {
            e.printStackTrace();
        }
        return scanner.nextInt();
    }
```

> 继承自Excepion是受查异常，继承自RuntimeExceptin则为非受查异常

**自定制异常举例：**
```java
package exception;

import java.util.Scanner;

//自定义异常
class UserException extends Exception{
    public UserException(String message) {
        super(message);
    }
}

class PasswordException extends Exception{
    public PasswordException(String message) {
        super(message);
    }
}

public class Test {
    private static final String USER_NAME = "zhangsan";
    private static final String PASSWORD = "123456";

    public static void login() throws UserException, PasswordException {
        Scanner scanner = new Scanner(System.in);
        System.out.println("请输入用户名");
        String userName = scanner.next();
        if(!userName.equals(USER_NAME)){
            //TODO出现情况抛出异常
            throw new UserException("用户名错误");
//            System.out.println("用户名错误");
//            return;
        }
        System.out.println("请输入密码");
        String password = scanner.next();
        if(!password.equals(PASSWORD)){
            throw new PasswordException("密码错误");
//            System.out.println("密码错误");
//            return;
        }
        System.out.println("登录成功");
    }

    public static void main(String[] args) {
        try{
            login();
        }catch (UserException e){
            e.printStackTrace();
        }catch(PasswordException e){
            e.printStackTrace();
        }
    }
}

```

